An exception
Traceback (most recent call last):
  File "main.py", line 2, in <module>
    raise NameError("Hi there")  
NameError: Hi there